# 例外処理

## 概要
例外処理はプログラムのエラーを適切に管理し、プログラムが予期せず終了することを防ぐ重要な機能です。

## 主要概念
例外とはプログラム実行中に発生するエラーのことで、try-except構文を使って捕捉・処理できます。

## 実際に試せるコード例

### 1. エラーが発生するケース

まずは例外処理を使わないと何が起こるかを確認してみましょう。

```python
# このコードを入力して実行してみましょう
numbers = [1, 2, 3]
index = 5

# 存在しないインデックスにアクセスするとエラーになります
numbers[index]  # IndexError: list index out of range
```

**実行結果**
```
IndexError: list index out of range
```

**解説**:
上記のコードでは、リスト`numbers`に存在しないインデックス`5`にアクセスしようとしています。
エラーが発生すると、プログラムはそこで終了してしまいます。

### 2. 基本的な例外処理

```python
# このコードを入力して実行してみましょう
numbers = [1, 2, 3]
index = 5

try:
    numbers[index]  # エラーになる処理
except:
    print("don't worry")  # エラーが発生した場合の処理
```

**実行結果**
```
don't worry
```

**解説**:
`try`ブロック内でエラーが発生しても、`except`ブロックでエラーを捕捉するため、
プログラムは終了せずに処理を続行します。ただし、このようにエラーの種類を指定せずに
`except`を使うのは推奨されません。

### 3. 特定の例外を捕捉する

```python
# このコードを入力して実行してみましょう
numbers = [1, 2, 3]
index = 5

try:
    numbers[index]
except IndexError:  # IndexErrorという特定の例外だけを捕捉
    print("don't worry")
```

**実行結果**
```
don't worry
```

**解説**:
特定の例外（ここでは`IndexError`）だけを捕捉することで、
他の予期しないエラーはそのまま表示されるようになります。これはデバッグに役立ちます。

### 4. 例外オブジェクトを取得する

```python
# このコードを入力して実行してみましょう
numbers = [1, 2, 3]
index = 5

try:
    numbers[index]
except IndexError as exc:  # エラーオブジェクトを変数excに代入
    print(f"don't worry: {exc}")
```

**実行結果**
```
don't worry: list index out of range
```

**解説**:
`as`キーワードを使うと、例外オブジェクトを変数に代入できます。
これによりエラーメッセージを取得し、より詳細な情報を表示できます。

### 5. 複数の例外を捕捉する

```python
# このコードを入力して実行してみましょう
numbers = [1, 2, 3]
index = 5
del numbers  # 変数numbersを削除

try:
    numbers[index]  # numbersが存在しないのでNameErrorが発生
except IndexError as exc:
    print(f"don't worry: {exc}")
except NameError as exc:
    print(f"don't worry: {exc}")
```

**実行結果**
```
don't worry: name 'numbers' is not defined
```

**解説**:
複数の`except`ブロックを用意することで、異なる種類の例外を別々に処理できます。
上記の例では、`numbers`変数を削除したため`NameError`が発生し、
2番目の`except`ブロックで捕捉されました。

### 6. 全ての例外を捕捉する

```python
# このコードを入力して実行してみましょう
numbers = [1, 2, 3]
index = 5

try:
    () + numbers  # タプルとリストは結合できないのでTypeErrorが発生
except IndexError as exc:
    print(f"don't worry: {exc}")
except NameError as exc:
    print(f"don't worry: {exc}")
except Exception as exc:  # その他のすべての例外を捕捉
    print(f"don't worry: {exc}")
```

**実行結果**
```
don't worry: can only concatenate tuple (not "list") to tuple
```

**解説**:
`Exception`は多くの例外の基底クラスです。`except Exception`を使うと、
指定していない例外も捕捉できますが、使いすぎるとバグの発見が難しくなるため注意が必要です。

### 7. 例外の階層構造

Pythonの例外は階層構造になっています。主な例外クラスは[Python公式ドキュメント](https://docs.python.org/3/library/exceptions.html#exception-hierarchy)で確認できます。ほとんどの例外は`Exception`クラスから派生しています。

### 8. finallyブロックの使用

```python
# このコードを入力して実行してみましょう
numbers = [1, 2, 3]
index = 5

try:
    () + numbers  # TypeErrorが発生
except IndexError as exc:
    print(f"don't worry: {exc}")
except NameError as exc:
    print(f"don't worry: {exc}")
except Exception as exc:
    print(f"don't worry: {exc}")
finally:
    print('clean up')  # 例外の有無に関わらず必ず実行される
```

**実行結果**
```
don't worry: can only concatenate tuple (not "list") to tuple
clean up
```

**解説**:
`finally`ブロックは、例外の発生有無にかかわらず、また例外を捕捉したかどうかにかかわらず、
必ず実行されます。リソースの解放など、必ず実行したい処理に適しています。

### 9. elseブロックの使用

```python
# このコードを入力して実行してみましょう
numbers = [1, 2, 3]
index = 0  # 有効なインデックス

try:
    numbers[index]  # エラーは発生しない
except IndexError as exc:
    print(f"don't worry: {exc}")
except NameError as exc:
    print(f"don't worry: {exc}")
except Exception as exc:
    print(f"don't worry: {exc}")
else:
    print('done')  # try内でエラーが発生しなかった場合に実行される
finally:
    print('clean up')  # 常に実行される
```

**実行結果**
```
done
clean up
```

**解説**:
`else`ブロックは`try`ブロック内でエラーが発生しなかった場合にのみ実行されます。
これにより、正常に処理が完了した場合の処理を明確に分けることができます。

### 10. 例外を発生させる

```python
# このコードを入力して実行してみましょう
try:
    raise IndexError('test error')  # 意図的に例外を発生させる
except IndexError as exc:
    print(exc)
```

**実行結果**
```
test error
```

**解説**:
`raise`キーワードを使うと、意図的に例外を発生させることができます。
テストやエラー条件を明示的に処理したい場合に使用します。

### 11. カスタム例外クラスの作成と使用

```python
# このコードを入力して実行してみましょう
class UppercaseError(Exception):
    pass  # Exceptionクラスを継承したカスタム例外

def check():
    words = ['apple', 'orange', 'banana']
    for word in words:
        if word.isupper():
            raise UppercaseError(word)  # 条件に合致したら例外を発生

check()  # 大文字の単語がないので例外は発生しない
```

**実行結果**
コードが正常に終了し、何も出力されません。

**解説**:
カスタム例外クラスを作成することで、プログラム固有のエラー状態を表現できます。
上記の例では、`UppercaseError`という例外クラスを定義し、大文字の単語がある場合に発生させるようにしています。

### 12. カスタム例外の実際の発生と捕捉

```python
# このコードを入力して実行してみましょう
class UppercaseError(Exception):
    pass

def check():
    words = ['APPLE', 'orange', 'banana']  # 'APPLE'が大文字
    for word in words:
        if word.isupper():
            raise UppercaseError(word)

try:
    check()  # 大文字の単語があるので例外が発生
except UppercaseError:
    print('this is my fault. go next')
```

**実行結果**
```
this is my fault. go next
```

**解説**:
このコードでは、`words`リストに大文字の単語`'APPLE'`があるため、
`UppercaseError`例外が発生し、`except`ブロックで捕捉されます。
カスタム例外を使うことで、コードの意図を明確にし、特定の状況に対応した
エラー処理を実装できます。
